Workbook

Sheet Dự trù từ Sales
A1: Tên sản phẩm cần dự trù - ngày yêu cầu dự trù
A2: STT | B2: Code hàng | C2: Tên hàng | D2: Hãng sản xuất - Sales không ghi | E2: Quy cách đóng gói | F2: Đơn vị tính | G2: Số lượng | H2: Sales/Viện | M2: LƯỚT XUỐNG DƯỚI ĐỂ TÌM ĐÚNG BẢNG: Tên sản phẩm cần dự trù - ngày yêu cầu dự trù
H3: A. Thái | I3: A. Phương | J3: A. Hoàng | K3: A.Cao
A4: 1 | B4: abcd | C4: abcd | D4: abcd | E4: abcd | F4: abcd | G4: 1 | H4: BVĐK Quang Khởi
A5: 2 | B5: abcd1 | C5: abcd1 | D5: abcd1 | E5: abcd1 | F5: abcd1 | G5: 1 | H5: BVĐK Quang Khởi
B6: abcd | C6: abcd | D6: abcd | E6: abcd | F6: abcd | G6: 1 | H6: BVĐK Quang Khởi
B7: abcd | C7: abcd | D7: abcd | E7: abcd | F7: abcd | G7: 1 | I7: Bệnh viện Nhi Hải Phòng
B8: abcd | C8: abcd | D8: abcd | E8: abcd | F8: abcd | G8: 1 | I8: Bệnh viện Nhi Hải Phòng
B9: abcd1 | C9: abcd1 | D9: abcd1 | E9: abcd1 | F9: abcd1 | G9: 1 | I9: Bệnh viện Nhi Hải Phòng
B10: abcd2 | C10: abcd2 | D10: abcd2 | E10: abcd2 | F10: abcd2 | G10: 1 | J10: BV ĐK Vĩnh Long
B11: abcd1 | C11: abcd1 | D11: abcd1 | E11: abcd1 | F11: abcd1 | G11: 1 | J11: BV ĐK Vĩnh Long
B12: abcd3 | C12: abcd3 | D12: abcd3 | E12: abcd3 | F12: abcd3 | G12: 1 | J12: BV ĐK Vĩnh Long
B13: abcd2 | C13: abcd2 | D13: abcd2 | E13: abcd2 | F13: abcd2 | G13: 1
B14: abcd4 | C14: abcd4 | D14: abcd4 | E14: abcd4 | F14: abcd4 | G14: 1 | K14: Gia Lai
K15: Gia Lai

Sheet Dự trù
A1: Tên sản phẩm cần dự trù - ngày yêu cầu dự trù
A2: STT | B2: Code hàng | C2: Tên hàng | D2: Hãng sản xuất | E2: Quy cách đóng gói | F2: Đơn vị tính | G2: Tổng số lượng | H2: Tồn kho | I2: Dự trù tính toán | J2: Dự trù thực tế - CHỐT ĐẶT HÀNG
A4: 1 | B4: =IFERROR(__xludf.DUMMYFUNCTION("UNIQUE(FILTER('Dự trù từ Sales'!B4:B15, 'Dự trù từ Sales'!B4:B15 <> """"))"),"abcd") -> abcd | C4: =IFERROR(VLOOKUP(B4, 'Dự trù từ Sales'!$B:$G, 2, FALSE), "") -> abcd | D4: =IFERROR(VLOOKUP(B4, 'Dự trù từ Sales'!$B:$G, 3, FALSE), "") -> abcd | E4: =IFERROR(VLOOKUP(B4, 'Dự trù từ Sales'!$B:$G, 4, FALSE), "") -> abcd | F4: =IFERROR(VLOOKUP(B4, 'Dự trù từ Sales'!$B:$G, 5, FALSE), "") -> abcd | G4: =SUMIF('Dự trù từ Sales'!B4:B14, B4, 'Dự trù từ Sales'!G4:G14) -> 4 | H4: 1 | I4: =(G4-H4)*1.2 -> 3.6 | J4: 3
B5: =IFERROR(__xludf.DUMMYFUNCTION("""COMPUTED_VALUE"""),"abcd1") -> abcd1 | C5: =IFERROR(VLOOKUP(B5, 'Dự trù từ Sales'!$B:$G, 2, FALSE), "") -> abcd1 | D5: =IFERROR(VLOOKUP(B5, 'Dự trù từ Sales'!$B:$G, 3, FALSE), "") -> abcd1 | E5: =IFERROR(VLOOKUP(B5, 'Dự trù từ Sales'!$B:$G, 4, FALSE), "") -> abcd1 | F5: =IFERROR(VLOOKUP(B5, 'Dự trù từ Sales'!$B:$G, 5, FALSE), "") -> abcd1 | G5: =SUMIF('Dự trù từ Sales'!B5:B15, B5, 'Dự trù từ Sales'!G5:G15) -> 3 | H5: 1 | I5: =(G5-H5)*1.2 -> 2.4 | J5: 5
B6: =IFERROR(__xludf.DUMMYFUNCTION("""COMPUTED_VALUE"""),"abcd2") -> abcd2 | C6: =IFERROR(VLOOKUP(B6, 'Dự trù từ Sales'!$B:$G, 2, FALSE), "") -> abcd2 | D6: =IFERROR(VLOOKUP(B6, 'Dự trù từ Sales'!$B:$G, 3, FALSE), "") -> abcd2 | E6: =IFERROR(VLOOKUP(B6, 'Dự trù từ Sales'!$B:$G, 4, FALSE), "") -> abcd2 | F6: =IFERROR(VLOOKUP(B6, 'Dự trù từ Sales'!$B:$G, 5, FALSE), "") -> abcd2 | G6: =SUMIF('Dự trù từ Sales'!B6:B16, B6, 'Dự trù từ Sales'!G6:G16) -> 2
B7: =IFERROR(__xludf.DUMMYFUNCTION("""COMPUTED_VALUE"""),"abcd3") -> abcd3 | C7: =IFERROR(VLOOKUP(B7, 'Dự trù từ Sales'!$B:$G, 2, FALSE), "") -> abcd3 | D7: =IFERROR(VLOOKUP(B7, 'Dự trù từ Sales'!$B:$G, 3, FALSE), "") -> abcd3 | E7: =IFERROR(VLOOKUP(B7, 'Dự trù từ Sales'!$B:$G, 4, FALSE), "") -> abcd3 | F7: =IFERROR(VLOOKUP(B7, 'Dự trù từ Sales'!$B:$G, 5, FALSE), "") -> abcd3 | G7: =SUMIF('Dự trù từ Sales'!B7:B17, B7, 'Dự trù từ Sales'!G7:G17) -> 1
B8: =IFERROR(__xludf.DUMMYFUNCTION("""COMPUTED_VALUE"""),"abcd4") -> abcd4 | C8: =IFERROR(VLOOKUP(B8, 'Dự trù từ Sales'!$B:$G, 2, FALSE), "") -> abcd4 | D8: =IFERROR(VLOOKUP(B8, 'Dự trù từ Sales'!$B:$G, 3, FALSE), "") -> abcd4 | E8: =IFERROR(VLOOKUP(B8, 'Dự trù từ Sales'!$B:$G, 4, FALSE), "") -> abcd4 | F8: =IFERROR(VLOOKUP(B8, 'Dự trù từ Sales'!$B:$G, 5, FALSE), "") -> abcd4 | G8: =SUMIF('Dự trù từ Sales'!B8:B18, B8, 'Dự trù từ Sales'!G8:G18) -> 1
A35: Hàng kháng sinh đồ - 20/01/2026
A36: STT | B36: Code hàng | C36: Tên hàng | D36: Hãng sản xuất | E36: Quy cách đóng gói | F36: Đơn vị tính | G36: Tổng số lượng | H36: Tồn kho | I36: Dự trù tính toán | J36: Dự trù thực tế - CHỐT ĐẶT HÀNG
A38: 1 | B38: ME0101 | C38: Gram Positive bacteria ID/AST | D38: Autobio Diagnostics Co., Ltd | E38: Hộp 10 test | F38: Hộp | G38: 21 | H38: 10 | I38: =(G38-H38)*1.2 -> 13.2 | J38: 13
A39: 2 | B39: MD0101 | C39: Non-Fermenting bacteria AST | D39: Autobio Diagnostics Co., Ltd | E39: Hộp 10 test | F39: Hộp | G39: 33 | H39: 7 | I39: =(G39-H39)*1.2 -> 31.2 | J39: 31
A40: 3 | B40: MD0501 | C40: Enterobacteriaceae AST | D40: Autobio Diagnostics Co., Ltd | E40: Hộp 10 test | F40: Hộp | G40: 45 | H40: 24 | I40: =(G40-H40)*1.2 -> 25.2 | J40: 25
A41: 4 | B41: MD0201 | C41: Streptococcus AST | D41: Autobio Diagnostics Co., Ltd | E41: Hộp 10 test | F41: Hộp | G41: 8 | H41: 7 | I41: =(G41-H41)*1.2 -> 1.2 | J41: 1
A42: 5 | B42: MD0401 | C42: Fungus AST | D42: Autobio Diagnostics Co., Ltd | E42: Hộp 10 test | F42: Hộp | G42: 6 | H42: 12 | I42: =(G42-H42)*1.2 -> -7.2
A43: 6 | B43: MG0102 | C43: 2#Tip | D43: Autobio Labtec | E43: 30 cái /hộp | F43: Hộp | G43: 129 | H43: 21 | I43: =(G43-H43)*1.2 -> 129.6 | J43: 130 | K43: CHO VÀO BA26-3
A44: 7 | B44: ME0202 | C44: Gram Negative bacteria ID/AST | D44: Autobio Diagnostics Co., Ltd | E44: Hộp 20 test | F44: Hộp | G44: 70 | H44: 5 | I44: =(G44-H44)*1.2 -> 78 | J44: 78
A45: 8 | B45: ME0102 | C45: Gram Positive bacteria ID/AST | D45: Autobio Diagnostics Co., Ltd | E45: Hộp 20 test | F45: Hộp | G45: 25 | H45: 4 | I45: =(G45-H45)*1.2 -> 25.2 | J45: 25
A46: 9 | C46: Đĩa mục tiêu | D46: Autobio Labtec | E46: Hộp 5 thẻ | F46: Hộp | G46: 4 | H46: 4 | I46: =(G46-H46)*1.2 -> 0 | J46: 2 | K46: CHO VÀO BA26-3
A47: 10 | B47: MSA02 | C47: Calib | D47: Autobio Diagnostics Co., Ltd | E47: 80T | F47: Hộp | G47: 0 | H47: 4 | I47: =(G47-H47)*1.2 -> -4.8
A48: 11 | B48: MSA03 | C48: CHCA | D48: Autobio Diagnostics Co., Ltd | E48: 4 Bottles(IVDR) | F48: Hộp | G48: 3 | H48: 7 | I48: =(G48-H48)*1.2 -> -4.8
A49: 12 | B49: MD0402 | C49: Fungus AST | D49: Autobio Diagnostics Co., Ltd | E49: Hộp 20 test | F49: Hộp | G49: 3 | H49: 0 | I49: =(G49-H49)*1.2 -> 3.6 | J49: 4
A50: 13 | B50: MD0202 | C50: Streptococcus AST | D50: Autobio Diagnostics Co., Ltd | E50: Hộp 20 test | F50: Hộp | G50: 1 | H50: 0 | I50: =(G50-H50)*1.2 -> 1.2 | J50: 1
A51: 14 | B51: ME0302 | C51: YEAST ID/AST | D51: Autobio Diagnostics Co., Ltd | E51: Hộp 20 test | F51: Hộp | G51: 2 | H51: 3 | I51: =(G51-H51)*1.2 -> -1.2
A52: 15 | B52: MD0302 | C52: Gram-positive bacteria AST | D52: Autobio Diagnostics Co., Ltd | E52: Hộp 20 test | F52: Hộp | G52: 15 | H52: 0 | I52: =(G52-H52)*1.2 -> 18 | J52: 18
A57: Hàng kháng sinh đồ - 22/01/2026
A58: STT | B58: Code hàng | C58: Tên hàng | D58: Hãng sản xuất | E58: Quy cách đóng gói | F58: Đơn vị tính | G58: Tổng số lượng | H58: Tồn kho | I58: Dự trù tính toán | J58: Dự trù thực tế - CHỐT ĐẶT HÀNG
A60: 1 | B60: ME0202 | C60: Gram Negative bacteria ID/AST | D60: Autobio Diagnostics Co., Ltd | E60: Hộp 20 test | F60: Hộp | G60: 30 | H60: 83 | I60: =(G60-H60)*1.2 -> -63.6
A61: 2 | B61: ME0102 | C61: Gram Positive bacteria ID/AST | D61: Autobio Diagnostics Co., Ltd | E61: Hộp 20 test | F61: Hộp | G61: 25 | H61: 29 | I61: =(G61-H61)*1.2 -> -4.8
A62: 3 | B62: MD0402 | C62: Fungus AST | D62: Autobio Diagnostics Co., Ltd | E62: Hộp 20 test | F62: Hộp | G62: 5 | H62: 4 | I62: =(G62-H62)*1.2 -> 1.2 | J62: 2
A63: 4 | B63: MD0202 | C63: Streptococcus AST | D63: Autobio Diagnostics Co., Ltd | E63: Hộp 20 test | F63: Hộp | G63: 3 | H63: 1 | I63: =(G63-H63)*1.2 -> 2.4 | J63: 3
A64: 5 | B64: ME0302 | C64: YEAST ID/AST | D64: Autobio Diagnostics Co., Ltd | E64: Hộp 20 test | F64: Hộp | G64: 5 | H64: 3 | I64: =(G64-H64)*1.2 -> 2.4 | J64: 3
A65: 6 | B65: MD0302 | C65: Gram-positive bacteria AST | D65: Autobio Diagnostics Co., Ltd | E65: Hộp 20 test | F65: Hộp | G65: 10 | H65: 18 | I65: =(G65-H65)*1.2 -> -9.6
A66: 7 | B66: MD0502 | C66: Enterobacteriaceae AST | D66: Autobio Diagnostics Co., Ltd | E66: Hộp 20 test | F66: Hộp | G66: 35 | H66: 0 | I66: =(G66-H66)*1.2 -> 42 | J66: 38
A67: 8 | B67: MD0102 | C67: Non-fermenting bacteria AST | D67: Autobio Diagnostics Co., Ltd | E67: Hộp 20 test | F67: Hộp | G67: 40 | H67: 0 | I67: =(G67-H67)*1.2 -> 48 | J67: 46

Sheet Đặt hàng
A1: Mã đơn hàng - ngày
A2: STT | B2: Code hàng | C2: Tên hàng | D2: Hãng sản xuất | E2: Quy cách đóng gói | F2: Đơn vị tính | G2: Số lượng | H2: PICK NGAY - Số lượng | I2: BACKORDER - Số lượng | J2: NOTE
A4: 1 | B4: {=UNIQUE('Dự trù'!B4:B15)} -> abcd | C4: ='Dự trù'!C4 -> abcd | D4: ='Dự trù'!D4 -> abcd | E4: ='Dự trù'!E4 -> abcd | F4: ='Dự trù'!F4 -> abcd | G4: =SUMIF('Dự trù'!B4:B14, B4, 'Dự trù'!J4:J14) -> 3 | H4: 3 | I4: =G4-H4 -> 0
B5: abcd1 | C5: ='Dự trù'!C5 -> abcd1 | D5: ='Dự trù'!D5 -> abcd1 | E5: ='Dự trù'!E5 -> abcd1 | F5: ='Dự trù'!F5 -> abcd1 | G5: =SUMIF('Dự trù'!B5:B15, B5, 'Dự trù'!J5:J15) -> 5 | H5: 4 | I5: =G5-H5 -> 1 | J5: Ví dụ: Cho vào đơn sau, thì phải nhập liệu mã này, số lượng này vào đơn sau
B6: abcd2 | C6: ='Dự trù'!C6 -> abcd2 | D6: ='Dự trù'!D6 -> abcd2 | E6: ='Dự trù'!E6 -> abcd2 | F6: ='Dự trù'!F6 -> abcd2 | G6: =SUMIF('Dự trù'!B6:B16, B6, 'Dự trù'!J6:J16) -> 0
B7: abcd3 | C7: ='Dự trù'!C7 -> abcd3 | D7: ='Dự trù'!D7 -> abcd3 | E7: ='Dự trù'!E7 -> abcd3 | F7: ='Dự trù'!F7 -> abcd3 | G7: =SUMIF('Dự trù'!B7:B17, B7, 'Dự trù'!J7:J17) -> 0
B8: abcd4 | C8: ='Dự trù'!C8 -> abcd4 | D8: ='Dự trù'!D8 -> abcd4 | E8: ='Dự trù'!E8 -> abcd4 | F8: ='Dự trù'!F8 -> abcd4 | G8: =SUMIF('Dự trù'!B8:B18, B8, 'Dự trù'!J8:J18) -> 0
A17: BA 25-15 - 13/01/2026
A18: STT | B18: Code hàng | C18: Tên hàng | D18: Hãng sản xuất | E18: Quy cách đóng gói | F18: Đơn vị tính | G18: Số lượng | H18: PICK NGAY - Số lượng | I18: BACKORDER - Số lượng | J18: NOTE
A20: 1 | B20: ME0101 | C20: Gram Positive bacteria ID/AST | D20: Autobio Diagnostics Co., Ltd | E20: 10tests | F20: Hộp | G20: 4 | H20: =G20 -> 4 | I20: =G20-H20 -> 0
A21: 2 | B21: ME0102 | C21: Gram Positive bacteria ID/AST | D21: Autobio Diagnostics Co., Ltd | E21: 10tests | F21: Hộp | G21: 4 | H21: =G21 -> 4 | I21: =G21-H21 -> 0 | J21: Ví dụ: Cho vào đơn sau, thì phải nhập liệu mã này, số lượng này vào đơn sau
A22: 3 | B22: ME0201 | C22: Gram Negative bacteria ID/AST | D22: Autobio Diagnostics Co., Ltd | E22: 10tests | F22: Hộp | G22: 5 | H22: =G22 -> 5 | I22: =G22-H22 -> 0
A23: 4 | B23: ME0202 | C23: Gram Negative bacteria ID/AST | D23: Autobio Diagnostics Co., Ltd | E23: 20tests | F23: Hộp | G23: 5 | H23: =G23 -> 5 | I23: =G23-H23 -> 0
A24: 5 | B24: ME0301 | C24: YEAST ID/AST | D24: Autobio Diagnostics Co., Ltd | E24: 10tests | F24: Hộp | G24: 3 | H24: =G24 -> 3 | I24: =G24-H24 -> 0
A25: 6 | B25: ME0302 | C25: YEAST ID/AST | D25: Autobio Diagnostics Co., Ltd | E25: 20tests | F25: Hộp | G25: 3 | H25: =G25 -> 3 | I25: =G25-H25 -> 0
A26: 7 | B26: MD0201 | C26: Streptococcus AST | D26: Autobio Diagnostics Co., Ltd | E26: 10T | F26: Hộp | G26: 3 | H26: =G26 -> 3 | I26: =G26-H26 -> 0
A27: 8 | B27: MD0401 | C27: Fungus AST | D27: Autobio Diagnostics Co., Ltd | E27: 10tests | F27: Hộp | G27: 5 | H27: =G27 -> 5 | I27: =G27-H27 -> 0
A28: 9 | B28: MSA01 | C28: Sample Pretreatment Reagent | D28: Autobio Diagnostics Co., Ltd | E28: 100tests(IVDR) | F28: Hộp | G28: 2 | H28: =G28 -> 2 | I28: =G28-H28 -> 0
A29: 10 | B29: MSA02 | C29: Calibrator for use with AUTOF MS | D29: Autobio Diagnostics Co., Ltd | E29: 80T | F29: Hộp | G29: 4 | H29: =G29 -> 4 | I29: =G29-H29 -> 0
A30: 11 | B30: MSA03 | C30: CHCA Matrix for use with AUTOF MS | D30: Autobio Diagnostics Co., Ltd | E30: 4 Bottles(IVDR) | F30: Hộp | G30: 5 | H30: =G30 -> 5 | I30: 0
A35: BA 26-01 - 20/01/2026
A36: STT | B36: Code hàng | C36: Tên hàng | D36: Hãng sản xuất | E36: Quy cách đóng gói | F36: Đơn vị tính | G36: Số lượng | H36: PICK NGAY - Số lượng | I36: BACKORDER - Số lượng | J36: NOTE | K36: 46086
A38: 1 | B38: ME0101 | C38: Gram Positive bacteria ID/AST | D38: Autobio Diagnostics Co., Ltd | E38: 10T | F38: Hộp | G38: =SUMIF('Dự trù'!B38:B52, B38, 'Dự trù'!J38:J52) -> 13 | H38: 13 | I38: =G38-H38 -> 0
A39: 2 | B39: MD0101 | C39: Non-fermenting bacteria AST | D39: Autobio Diagnostics Co., Ltd | E39: 10T | F39: Hộp | G39: =SUMIF('Dự trù'!B39:B53, B39, 'Dự trù'!J39:J53) -> 31 | H39: 31 | I39: =G39-H39 -> 0 | J39: ME0202 - Gram Negative bacteria ID/AST - 5/3 mới có hàng
A40: 3 | B40: MD0501 | C40: Enterobacteriaceae AST | D40: Autobio Diagnostics Co., Ltd | E40: 10T | F40: Hộp | G40: =SUMIF('Dự trù'!B40:B54, B40, 'Dự trù'!J40:J54) -> 25 | H40: 25 | I40: =G40-H40 -> 0
A41: 4 | B41: MD0201 | C41: Streptococcus AST | D41: Autobio Diagnostics Co., Ltd | E41: 10T | F41: Hộp | G41: =SUMIF('Dự trù'!B41:B55, B41, 'Dự trù'!J41:J55) -> 1 | H41: 1 | I41: =G41-H41 -> 0
A42: 5 | B42: ME0202 | C42: Gram Negative bacteria ID/AST | D42: Autobio Diagnostics Co., Ltd | E42: 20T | F42: Hộp | G42: =SUMIF('Dự trù'!B42:B56, B42, 'Dự trù'!J42:J56) -> 78 | H42: 30 | I42: =G42-H42 -> 48
A43: 6 | B43: ME0102 | C43: Gram Positive bacteria ID/AST | D43: Autobio Diagnostics Co., Ltd | E43: 20T | F43: Hộp | G43: =SUMIF('Dự trù'!B43:B57, B43, 'Dự trù'!J43:J57) -> 25 | H43: 25 | I43: =G43-H43 -> 0
A44: 7 | B44: MD0402 | C44: Fungus AST | D44: Autobio Diagnostics Co., Ltd | E44: 20T | F44: Hộp | G44: =SUMIF('Dự trù'!B44:B58, B44, 'Dự trù'!J44:J58) -> 4 | H44: 4 | I44: =G44-H44 -> 0
A45: 8 | B45: MD0202 | C45: Streptococcus AST | D45: Autobio Diagnostics Co., Ltd | E45: 20T | F45: Hộp | G45: =SUMIF('Dự trù'!B45:B59, B45, 'Dự trù'!J45:J59) -> 1 | H45: 1 | I45: =G45-H45 -> 0
A46: 9 | B46: MD0302 | C46: Gram Positive bacteria AST | D46: Autobio Diagnostics Co., Ltd | E46: 20T | F46: Hộp | G46: =SUMIF('Dự trù'!B46:B60, B46, 'Dự trù'!J46:J60) -> 18 | H46: 18 | I46: =G46-H46 -> 0
A57: BA 26-04 - 22/01/2026
A58: STT | B58: Code hàng | C58: Tên hàng | D58: Hãng sản xuất | E58: Quy cách đóng gói | F58: Đơn vị tính | G58: Số lượng | H58: PICK NGAY - Số lượng | I58: BACKORDER - Số lượng | J58: NOTE
A60: 1 | B60: {=UNIQUE('Dự trù'!B60:B71)} -> ME0202 | C60: ='Dự trù'!C60 -> Gram Negative bacteria ID/AST | D60: ='Dự trù'!D60 -> Autobio Diagnostics Co., Ltd | E60: ='Dự trù'!E60 -> Hộp 20 test | F60: ='Dự trù'!F60 -> Hộp | G60: =SUMIF('Dự trù'!B60:B70, B60, 'Dự trù'!J60:J70) -> 0 | I60: =G60-H60 -> 0
B61: ME0102 | C61: ='Dự trù'!C61 -> Gram Positive bacteria ID/AST | D61: ='Dự trù'!D61 -> Autobio Diagnostics Co., Ltd | E61: ='Dự trù'!E61 -> Hộp 20 test | F61: ='Dự trù'!F61 -> Hộp | G61: =SUMIF('Dự trù'!B61:B71, B61, 'Dự trù'!J61:J71) -> 0 | I61: =G61-H61 -> 0 | J61: MD0502 - Enterobacteriaceae AST - CHƯA CÓ KẾ HOẠCH SẢN XUẤT
B62: MD0402 | C62: ='Dự trù'!C62 -> Fungus AST | D62: ='Dự trù'!D62 -> Autobio Diagnostics Co., Ltd | E62: ='Dự trù'!E62 -> Hộp 20 test | F62: ='Dự trù'!F62 -> Hộp | G62: =SUMIF('Dự trù'!B62:B72, B62, 'Dự trù'!J62:J72) -> 2 | H62: 2 | I62: =G62-H62 -> 0
B63: MD0202 | C63: ='Dự trù'!C63 -> Streptococcus AST | D63: ='Dự trù'!D63 -> Autobio Diagnostics Co., Ltd | E63: ='Dự trù'!E63 -> Hộp 20 test | F63: ='Dự trù'!F63 -> Hộp | G63: =SUMIF('Dự trù'!B63:B72, B63, 'Dự trù'!J63:J72) -> 3 | H63: 3 | I63: =G63-H63 -> 0
B64: ME0302 | C64: ='Dự trù'!C64 -> YEAST ID/AST | D64: ='Dự trù'!D64 -> Autobio Diagnostics Co., Ltd | E64: ='Dự trù'!E64 -> Hộp 20 test | F64: ='Dự trù'!F64 -> Hộp | G64: =SUMIF('Dự trù'!B64:B72, B64, 'Dự trù'!J64:J72) -> 3 | H64: 3 | I64: =G64-H64 -> 0
B65: MD0302 | C65: ='Dự trù'!C65 -> Gram-positive bacteria AST | D65: ='Dự trù'!D65 -> Autobio Diagnostics Co., Ltd | E65: ='Dự trù'!E65 -> Hộp 20 test | F65: ='Dự trù'!F65 -> Hộp | G65: =SUMIF('Dự trù'!B65:B72, B65, 'Dự trù'!J65:J72) -> 0 | I65: =G65-H65 -> 0
B66: MD0502 | C66: ='Dự trù'!C66 -> Enterobacteriaceae AST | D66: ='Dự trù'!D66 -> Autobio Diagnostics Co., Ltd | E66: ='Dự trù'!E66 -> Hộp 20 test | F66: ='Dự trù'!F66 -> Hộp | G66: =SUMIF('Dự trù'!B66:B72, B66, 'Dự trù'!J66:J72) -> 38 | H66: 22 | I66: =G66-H66 -> 16
...

Sheet Nhập khẩu
B1: PTN – Phiếu tiếp nhận
B2: Phân loại
B3: Packing List
B4: Bill of lading
B5: Hóa đơn cước vận chuyển
B6: Thông báo hang đến
B7: Commercial Invoice
B8: Nếu bên khác công bố phân loại thì thêm ủy quyền
B9: THÔNG TIN SHIPMENTS:
A10: Trạng thái | B10: PI NO. | C10: Mã bill MAWB No. | D10: Số hiệu chuyến bay | E10: Tên | F10: GIÁ | G10: Đơn vị báo giá | H10: Ngày gửi hàng | I10: Dự kiến ngày tới | J10: Thực tế ngày tới | K10: Số kiện | L10: G.W. (Total KG)
A11: In Transit | B11: KHL-MT-20251212 | C11: 784-41877146 | D11: CZ8177 | E11: Máy đọc Elisa - ST-360 Microplate Reader Máy rửa Elisa - ST-36W Microplate Washer | G11: AIR A ĐIỆP | H11: 24/12/2025 | I11: 27/12/2025 | K11: 2 set 2 set | L11: 56
A12: In Transit | B12: BA26-04 | C12: 888-60665001 | D12: JD647 | E12: AST CARD | F12: $1780 | G12: Autobio | H12: 46056 | K12: 50 cartons | L12: 890
A13: In Transit | B13: BA26-04 | D13: CX051 CX741 | E13: dangerous goods | F13: $620 | G13: Autobio | H13: 46058 | K13: 2 cartons | L13: 10
A14: In Transit | B14: máy đo độ đục | C14: SF0252788211653 | E14: máy đo độ đục | G14: Autobio | H14: 46055 | I14: Hàng vẫn đang ở tq

Sheet Nhập kho
A1: IN PKL - KIỂM HÀNG

Sheet Đơn vị vận chuyển
A2: Tên đơn vị vận chuyển | B2: SDT | C2: Người liên hệ | D2: Hợp đồng, chứng từ yêu cầu | E2: Chuyên tuyến | F2: Đơn hàng cần vận chuyển 1
F3: Tốc độ phản hồi - tương tác | G3: Giá | H3: Độ tin cậy - Đúng hẹn | I3: Mức độ phù hợp
